Workbook

Sheet Sheet1
A1: Bp Number | B1: District | C1: Farmer Nam | D1: Name in BP | E1: Farm Name | F1: Address | G1: State | H1: Lat | I1: Long | J1: Area (Ac) | K1: 2025-26 RC | L1: Total GC p | M1: Coffee Pro | N1: village | O1: phone number | P1: Cluster | Q1: Day | R1: Team
A2: IN4C4-BP221-HR221 | B2: Kodagu | C2: Poonacha P B | D2: Poonacha Patacharuvanda Bolka | E2: Poonacha Patacharuvanda Bolka | F2: Chelavara (V) Cheyandane (P), Madikeri | G2: Karnataka | H2: 12.212749 | I2: 75.684119 | J2: 10 | K2: 440 | L2: 11880 | M2: 4 | N2: CHELAVARA | O2: 9482926593 | P2: 20 | Q2: 1 | R2: Team 1 | S2: =IF(COUNTIF(Sheet2!$A:$A,A2)>0,1,"")
A3: IN4C4-BP172-HR172 | B3: Kodagu | C3: Santosh Kumar B V | D3: Santosh Kumar | E3: Santosh estate | F3: Karada, Virajpet | G3: Karnataka | H3: 12.215579 | I3: 75.709182 | J3: 8 | K3: 325 | L3: 8778 | M3: 3.2 | N3: KAVAOLA | O3: 9632322069 | P3: 20 | Q3: 1 | R3: Team 1 | S3: =IF(COUNTIF(Sheet2!$A:$A,A3)>0,1,"")
A4: IN4C1-BP733-HR733 | B4: Kodagu | C4: Laveen C U | D4: Laveen Chandira Uthaiah | E4: Laveen Chandira Uthaiah | F4: Kokeri (V), Cheyyandane (P), Madikeri | G4: Karnataka | H4: 12.237561 | I4: 75.68452 | J4: 3.5 | K4: 120 | L4: 3240 | M4: 1.4 | N4: KOKERI | O4: 8152018149 / 8277754623 | P4: 20 | Q4: 1 | R4: Team 1 | S4: =IF(COUNTIF(Sheet2!$A:$A,A4)>0,1,"")
A5: IN4C5-BP302-BE302 | B5: Kodagu | C5: Kodira Monnappa Kushalappa | D5: Kodira Monnappa Kushalappa | E5: Kodira Monnappa Kushalappa Farm | F5: Kadanga | G5: Karnataka | H5: 12.225626 | I5: 75.719645 | J5: 70 | K5: 2300 | L5: 62100 | M5: 28.3 | N5: KADANGAMARUR | O5: 9480616060 | P5: 20 | Q5: 1 | R5: Team 1 | S5: =IF(COUNTIF(Sheet2!$A:$A,A5)>0,1,"")
A6: IN4C7-BP1121-TT1121 | B6: Kodagu | C6: Usman K E | D6: Usman Kodapadi Ebrahim | E6: Usman Kodapadi Ebrahim Farm | F6: Kadanga | G6: Karnatka | H6: 12.226335 | I6: 75.733178 | J6: 12 | K6: 400 | L6: 10800 | M6: 4.9 | N6: KADANGAMARUR | O6: 9008976843 | P6: 20 | Q6: 1 | R6: Team 1 | S6: =IF(COUNTIF(Sheet2!$A:$A,A6)>0,1,"")
A7: IN4C4-BP154-HR154 | B7: Kodagu | C7: Laxmanna B K | D7: Laxmana Belliyanda Kariappa | E7: Laxmanna estate | F7: Nariyanda, Virajpet | G7: Karnataka | H7: 12.242164 | I7: 75.709708 | J7: 16 | K7: 660 | L7: 17820 | M7: 6.5 | N7: KODAGU | O7: 9482105162 | P7: 20 | Q7: 1 | R7: Team 1 | S7: =IF(COUNTIF(Sheet2!$A:$A,A7)>0,1,"")
A8: IN4C5-BP315-BE315 | B8: Kodagu | C8: Nerpanda Mandanna Ayyappa | D8: Nerpanda Mandanna Ayyappa | E8: Nerpanda Mandanna Ayyappa Farm | F8: Karada | G8: Karnataka | H8: 12.240574 | I8: 75.719542 | J8: 16 | K8: 450 | L8: 12150 | M8: 6.5 | N8: KODAGU | O8: 9916910067 | P8: 20 | Q8: 1 | R8: Team 1 | S8: =IF(COUNTIF(Sheet2!$A:$A,A8)>0,1,"")
A9: IN4C7-BP640-TT640 | B9: Kodagu | C9: Sharanu B T | D9: Sharanu Boverianda Thammaiah | E9: Sharanu Boverianda Thammaiah Farm | F9: Cheyandane | G9: Karnataka | H9: 12.226263 | I9: 75.705648 | J9: 11 | K9: 230 | L9: 6210 | M9: 4.4 | N9: KODAGU | O9: 9449169957 | P9: 20 | Q9: 1 | R9: Team 1 | S9: =IF(COUNTIF(Sheet2!$A:$A,A9)>0,1,"")
A10: IN4C7-BP58-SL58 | B10: Kodagu | C10: Paramesh N S | D10: Paramesh Nidtha Somappa | E10: Paramesh Nidtha Somappa Farm | F10: Nidtha (V&P) | G10: Karnataka | H10: 12.70386 | I10: 75.92416 | J10: 2 | K10: 34 | L10: 918 | M10: 0.8 | N10: NIDTHA | O10: 9482668762 | P10: 5 | Q10: 1 | R10: Team 2 | S10: =IF(COUNTIF(Sheet2!$A:$A,A10)>0,1,"")
A11: IN4C6-BP303-AM303 | B11: Kodagu | C11: Thirugnan Murthy S | D11: Thirugnan Murthy S | E11: Paary Estate | F11: Gudegaale(V), Hanelli (p0< Somwarpet | G11: Karnataka | H11: 12.72409 | I11: 75.899343 | J11: 35 | K11: 470 | L11: 12690 | M11: 14.2 | N11: HULSE | O11: 9482351416 (Kantharaj) | P11: 5 | Q11: 1 | R11: Team 2 | S11: =IF(COUNTIF(Sheet2!$A:$A,A11)>0,1,"")
A12: IN4C5-BP1101-VC1101 | B12: Kodagu | C12: Sunjog NB | D12: Nidda Rajasekhar Sunjog | E12: Mathegodu Est | F12: Gopalpura Kenkere Rd, Sanivarsanthe | G12: Karnataka | H12: 12.700643 | I12: 75.892252 | J12: 50 | K12: 1500 | L12: 40500 | M12: 20.2 | N12: GOPALPURA | O12: 9901903920 | P12: 5 | Q12: 1 | R12: Team 2 | S12: =IF(COUNTIF(Sheet2!$A:$A,A12)>0,1,"")
A13: IN4C6-BP296-AM296 | B13: Kodagu | C13: S V Chinna Sevugam Chettiar | D13: S V Chinna Sevugam Chettiar | E13: Gopalpura Estate | F13: Goplapura (V&P), Shanivarsanthe | G13: Karnataka | H13: 12.703776 | I13: 75.89327 | J13: 20 | K13: 400 | L13: 10800 | M13: 8.1 | N13: GOPALPURA | O13: 9444495583 | P13: 5 | Q13: 1 | R13: Team 2 | S13: =IF(COUNTIF(Sheet2!$A:$A,A13)>0,1,"")
A14: IN4C6-BP297-AM297 | B14: Kodagu | C14: M Manickam Chettiar | D14: Meyappan Manickam Chettiar | E14: Gopalpura Estate | F14: Goplapura (V&P), Shanivarsanthe | G14: Karnataka | H14: 12.702152 | I14: 75.896288 | J14: 20 | K14: 425 | L14: 11478 | M14: 8.1 | N14: GOPALPURA | O14: 9444495583 | P14: 5 | Q14: 1 | R14: Team 2 | S14: =IF(COUNTIF(Sheet2!$A:$A,A14)>0,1,"")
A15: IN4C6-BP298-AM298 | B15: Kodagu | C15: RM Sevugan Chettiar | D15: Ramanathan Sevugan Chettiar | E15: Gopalpura Estate | F15: Goplapura (V&P), Shanivarsanthe | G15: Karnataka | H15: 12.703186 | I15: 75.89323 | J15: 20 | K15: 400 | L15: 10800 | M15: 8.1 | N15: GOPALPURA | O15: 9444495583 | P15: 5 | Q15: 1 | R15: Team 2 | S15: =IF(COUNTIF(Sheet2!$A:$A,A15)>0,1,"")
A16: IN4C6-BP299-AM299 | B16: Kodagu | C16: SV Meyappan | D16: Sevugan Meyappan | E16: Gopalpura Estate | F16: Goplapura (V&P), Shanivarsanthe | G16: Karnataka | H16: 12.704419 | I16: 75.892933 | J16: 20 | K16: 425 | L16: 11478 | M16: 8.1 | N16: GOPALPURA | O16: 9444495583 | P16: 5 | Q16: 1 | R16: Team 2 | S16: =IF(COUNTIF(Sheet2!$A:$A,A16)>0,1,"")
A17: IN4C6-BP300-AM300 | B17: Kodagu | C17: M Vishalakshi | D17: Manickam Chettiar Vishalakshi | E17: Gopalpura Estate | F17: Dhodel Kothur (V0, Shanivarsanthe | G17: Karnataka | H17: 12.701849 | I17: 75.895535 | J17: 40 | K17: 775 | L17: 20928 | M17: 16.2 | N17: GOPALPURA | O17: 9444495583 | P17: 5 | Q17: 1 | R17: Team 2 | S17: =IF(COUNTIF(Sheet2!$A:$A,A17)>0,1,"")
A18: IN4C6-BP301-AM301 | B18: Kodagu | C18: Senthil Nathan M | D18: Senthilnatahn Manickam | E18: Jayamma Estate | F18: Shanivarsanthe | G18: Karnataka | H18: 12.700881 | I18: 75.896072 | J18: 11 | K18: 210 | L18: 5670 | M18: 4.5 | N18: GOPALPURA | O18: 9444495583 | P18: 5 | Q18: 1 | R18: Team 2 | S18: =IF(COUNTIF(Sheet2!$A:$A,A18)>0,1,"")
A19: IN4C6-BP302-AM302 | B19: Kodagu | C19: T Kalairaj | D19: Thiyagarajan Kalairaj | E19: Karbaka Vinayakam Estate | F19: Shanivarsanthe | G19: Karnataka | H19: 12.706556 | I19: 75.89862 | J19: 8 | K19: 160 | L19: 4320 | M19: 3.2 | N19: GOPALPURA | O19: 9444495583 | P19: 5 | Q19: 1 | R19: Team 2 | S19: =IF(COUNTIF(Sheet2!$A:$A,A19)>0,1,"")
A20: IN4C6-BP304-AM304 | B20: Kodagu | C20: Rajashekar H M | D20: Rajashekar Honnugudi Mahalingappa | E20: Mallikarjuna Estate | F20: Kyathe (V), Kodlipet | G20: Karnataka | H20: 12.78985 | I20: 75.874813 | J20: 12 | K20: 350 | L20: 9450 | M20: 4.9 | N20: KODLIPET | O20: 9448976631 | P20: 5 | Q20: 1 | R20: Team 2 | S20: =IF(COUNTIF(Sheet2!$A:$A,A20)>0,1,"")
A21: IN4C1-BP325-BP325 | B21: Kodagu | C21: Viji Jhon | D21: Viji Jhon | E21: Karappara Estate | F21: Karappara estate, Yavakapadi village, Kakkabe | G21: Karnataka | H21: 12.23317 | I21: 75.64117 | J21: 73 | K21: 2670 | L21: 72090 | M21: 29.6 | N21: NALADI | O21: 9448406405 | P21: 33 | Q21: 2 | R21: Team 1 | S21: =IF(COUNTIF(Sheet2!$A:$A,A21)>0,1,"")
A22: IN4C4-BP207-HR207 | B22: Kodagu | C22: Uthappa C K | D22: Uthappa Chandira Kandiara | E22: Uthappa estate | F22: Napoklu, Madikeri | G22: Karnataka | H22: 12.245053 | I22: 75.652266 | J22: 54 | K22: 1800 | L22: 48600 | M22: 21.9 | N22: NALADI | O22: 9845726921 | P22: 33 | Q22: 2 | R22: Team 1 | S22: =IF(COUNTIF(Sheet2!$A:$A,A22)>0,1,"")
A23: IN4C4-BP211-HR211 | B23: Kodagu | C23: Shayla N P | D23: Shayla Naresh Pandanda | E23: Pandanda estate | F23: Napoklu, Madikeri | G23: Karnataka | H23: 12.247851 | I23: 75.644058 | J23: 38 | K23: 870 | L23: 23490 | M23: 15.4 | N23: NALADI | O23: 9880573323 | P23: 33 | Q23: 2 | R23: Team 1 | S23: =IF(COUNTIF(Sheet2!$A:$A,A23)>0,1,"")
... A32: IN4C7-BP1104-TT1104 | B32: Kodagu | C32: Savithri A T | D32: Savithri Anjaparavanda Thimmaiah | E32: Savithri Anjaparavanda Thimmaiah Farm | F32: Yavakapadi, Kunjila | G32: Karnatka | H32: 12.244595 | I32: 75.654401 | J32: 8 | K32: 280 | L32: 7560 | M32: 3.2 | N32: NALADI | O32: 9481859217 | P32: 33 | Q32: 2 | R32: Team 1 | S32: =IF(COUNTIF(Sheet2!$A:$A,A32)>0,1,"")
A33: IN4C7-BP1105-TT1105 | B33: Kodagu | C33: Thimmaiah A S | D33: Thimmaiah Anjaparavanda Subbaiah | E33: Thimmaiah Anjaparavanda Subbaiah Farm | F33: Yavakapadi, Kunjila | G33: Karnatka | H33: 12.244595 | I33: 75.654862 | J33: 18 | K33: 600 | L33: 16200 | M33: 7.3 | N33: NALADI | O33: 9481859218/7483774737 | P33: 33 | Q33: 2 | R33: Team 1 | S33: =IF(COUNTIF(Sheet2!$A:$A,A33)>0,1,"")
A34: IN4C7-BP1116-TT1116 | B34: Kodagu | C34: Vivek A M | D34: Vivek Apparanda Mandanna | E34: Vivek Apparanda Mandanna Farm | F34: Yavakapadi, Kunjila | G34: Karnatka | H34: 12.236709 | I34: 75.641721 | J34: 17 | K34: 700 | L34: 18900 | M34: 6.9 | N34: NALADI | O34: 9480731813/9901339255 | P34: 33 | Q34: 2 | R34: Team 1 | S34: =IF(COUNTIF(Sheet2!$A:$A,A34)>0,1,"")
A35: IN4C7-BP1117-TT1117 | B35: Kodagu | C35: Poonacha A M | D35: Poonacha Apparanda Mandanna | E35: Poonacha Apparanda Mandanna Farm | F35: Yavakapadi, Kunjila | G35: Karnatka | H35: 12.246753 | I35: 75.647068 | J35: 19 | K35: 600 | L35: 16200 | M35: 7.7 | N35: NALADI | O35: 0 | P35: 33 | Q35: 2 | R35: Team 1 | S35: =IF(COUNTIF(Sheet2!$A:$A,A35)>0,1,"")
A36: IN4C7-BP1119-TT1119 | B36: Kodagu | C36: Mandanna A P | D36: Mandanna Apparanda Ponnappa | E36: Mandanna Apparanda Ponnappa Farm | F36: Yavakapadi, Kunjila | G36: Karnatka | H36: 12.245424 | I36: 75.649551 | J36: 17 | K36: 500 | L36: 13500 | M36: 6.9 | N36: NALADI | O36: 9686401945 | P36: 33 | Q36: 2 | R36: Team 1 | S36: =IF(COUNTIF(Sheet2!$A:$A,A36)>0,1,"")
A37: IN4C7-BP381-TR381 | B37: Kodagu | C37: Kabbinkad Estate | D37: Kabbinkad Estate | E37: Kabbinkad Estate Farm | F37: Yevakapadi, Napoklu | G37: Karnataka | H37: 12.223995 | I37: 75.650682 | J37: 46 | K37: 520 | L37: 14040 | M37: 18.6 | N37: NALADI | O37: 9481840999 (jeevan) | P37: 33 | Q37: 2 | R37: Team 1 | S37: =IF(COUNTIF(Sheet2!$A:$A,A37)>0,1,"")
A38: IN4C5-BP394-HR394 | B38: Kodagu | C38: Jose Mathew | D38: Jose Mathew | E38: Jose Mathew Farm | F38: Chelavara, Cheyandane | G38: Karnataka | H38: 12.20478 | I38: 75.65735 | J38: 40 | K38: 1100 | L38: 29700 | M38: 16.2 | N38: MARANDODA | O38: 9447488231 / 9449255179 9 Bino) | P38: 33 | Q38: 2 | R38: Team 1 | S38: =IF(COUNTIF(Sheet2!$A:$A,A38)>0,1,"")
A39: IN4C7-BP1107-TT1107 | B39: Kodagu | C39: Dayananda M Y | D39: Dayananda Mukkatti Yadava | E39: Dayananda Mukkatti Yadava Farm | F39: Yavakapadi, Kunjila | G39: Karnatka | H39: 12.238192 | I39: 75.661461 | J39: 6 | K39: 240 | L39: 6480 | M39: 2.4 | N39: MARANDODA | O39: 9591175575 | P39: 33 | Q39: 2 | R39: Team 1 | S39: =IF(COUNTIF(Sheet2!$A:$A,A39)>0,1,"")
A40: IN4C7-BP310-HR310 | B40: Kodagu | C40: Dileep M C | D40: Dileep Mukkati chittiappa | E40: Dileep Mukkati chittiappa Farm | F40: Marandoda, Napoklu | G40: Karnataka | H40: 12.237011 | I40: 75.664875 | J40: 10 | K40: 180 | L40: 4860 | M40: 4 | N40: MARANDODA | O40: 9686048749 | P40: 33 | Q40: 2 | R40: Team 1 | S40: =IF(COUNTIF(Sheet2!$A:$A,A40)>0,1,"")
A41: IN4C7-BP311-HR311 | B41: Kodagu | C41: Nanaiah C D | D41: Nanaiah Choyamadanda Devaiah | E41: Nanaiah Choyamadanda Devaiah Farm | F41: Marandoda, Napoklu | G41: Karnataka | H41: 12.233109 | I41: 75.661924 | J41: 4 | K41: 140 | L41: 3780 | M41: 1.7 | N41: MARANDODA | O41: 9483495955 | P41: 33 | Q41: 2 | R41: Team 1 | S41: =IF(COUNTIF(Sheet2!$A:$A,A41)>0,1,"")
A42: IN4C6-BP305-AM305 | B42: Kodagu | C42: Preetham Basappa | D42: Preetham Basappa | E42: Ist Kushboor Estate | F42: Balagunda, Somwarpet | G42: Karnataka | H42: 12.572556 | I42: 75.847338 | J42: 75 | K42: 1100 | L42: 29700 | M42: 30.4 | N42: KUSUBUR | O42: 9845024270 | P42: 36 | Q42: 2 | R42: Team 2 | S42: =IF(COUNTIF(Sheet2!$A:$A,A42)>0,1,"")
A43: IN4C5-BP1147-VC1147 | B43: Kodagu | C43: Dharmakumar BT | D43: Bilimaga Thimmashetty Dharmakumar | E43: Bilimaga | F43: Abimatta, Santhahally | G43: Karnataka | H43: 12.598771 | I43: 75.850191 | J43: 15 | K43: 300 | L43: 8100 | M43: 6.1 | N43: BALUGUNDA | O43: 9902322525 | P43: 36 | Q43: 2 | R43: Team 2 | S43: =IF(COUNTIF(Sheet2!$A:$A,A43)>0,1,"")
A44: IN4C7-BP552-TR552 | B44: Kodagu | C44: Bymana Gagan K | D44: Bymana Gagan Kuttappa | E44: Bymana Gagan Kuttappa Farm | F44: Bajegundi,Somwarpet | G44: Karnataka | H44: 12.576079 | I44: 75.839973 | J44: 15 | K44: 320 | L44: 8640 | M44: 6.1 | N44: BALUGUNDA | O44: 9945505050 | P44: 36 | Q44: 2 | R44: Team 2 | S44: =IF(COUNTIF(Sheet2!$A:$A,A44)>0,1,"")
A45: IN4C5-BP1148-VC1148 | B45: Kodagu | C45: Somesh KS | D45: Kibetta Santhappa Somesh | E45: Kibbetta | F45: Kibbetta, Somawarpet | G45: Karnataka | H45: 12.606575 | I45: 75.865136 | J45: 8 | K45: 160 | L45: 4320 | M45: 3.2 | N45: MASAGODU | O45: 9448870960 | P45: 36 | Q45: 2 | R45: Team 2 | S45: =IF(COUNTIF(Sheet2!$A:$A,A45)>0,1,"")
A46: IN4C5-BP400-HR400 | B46: Kodagu | C46: Hithesh S T | D46: Hithesh Suliyakodi Thimmaiah | E46: Hithesh Suliyakodi Thimmaiah Farm | F46: Gonimaroor, Somwarpet | G46: Karnataka | H46: 12.604042 | I46: 75.919206 | J46: 10 | K46: 320 | L46: 8640 | M46: 4 | N46: GONIMARUR | O46: 9901281643 | P46: 36 | Q46: 2 | R46: Team 2 | S46: =IF(COUNTIF(Sheet2!$A:$A,A46)>0,1,"")
A47: IN4C5-BP1146-VC1146 | B47: Kodagu | C47: Dharmappa PP | D47: Puttanamane Poovaiah Dharmappa | E47: SR Estate | F47: Abimatta, Santhahally | G47: Karnataka | H47: 12.630395 | I47: 75.809701 | J47: 5 | K47: 60 | L47: 1620 | M47: 2 | N47: ABBIMATTA | O47: 9448108189 | P47: 36 | Q47: 2 | R47: Team 2 | S47: =IF(COUNTIF(Sheet2!$A:$A,A47)>0,1,"")
A48: IN4C7-BP597-TR597 | B48: Kodagu | C48: Kiran Subbaiah | D48: Kiran Subbaiah | E48: Kiran Subbaiah Farm | F48: Virajpet | G48: Karnataka | H48: 12.625255 | I48: 75.859651 | J48: 20 | K48: 630 | L48: 17010 | M48: 8.1 | N48: HONNE HANAKODU | O48: 7510833777 | P48: 36 | Q48: 2 | R48: Team 2 | S48: =IF(COUNTIF(Sheet2!$A:$A,A48)>0,1,"")
...

Sheet Sheet2
A1: Bp Number farms
A2: IN4C1-BP269-SD82 | B2: 1
A3: IN4C1-BP309-SD122 | B3: 1
A4: IN4C1-BP328-BP328 | B4: 1
A5: IN4C1-BP348-BP348 | B5: 1
A6: IN4C1-BP349-BP349 | B6: 1
A7: IN4C1-BP375-BP375 | B7: 1
A8: IN4C1-BP542-BE542 | B8: 1
A9: IN4C1-BP585-BE585 | B9: 1
A10: IN4C4-BP18-HR18 | B10: 1
A11: IN4C4-BP238-HR238 | B11: 1
A12: IN4C4-BP239-HR239 | B12: 1
A13: IN4C4-BP240-HR240 | B13: 1
... A118: IN4C7-BP616-TT616 | B118: 1
